Workbook

Sheet Ejercicio
B2: Considere las siguientes transacciones y contabilice en libro diario, libro mayor. Efectúe, además Balance General de 8 columnas y Estado de Resultados al 31.12.2012 :
B4: La empresa “CIM”, inicia actividades el 01.02.2012, con lo siguiente:
B6: EFECTIVO | C6: 5000000
B7: MATERIALES | C7: 10000000
B8: VEHICULO | C8: 6500000
B9: DOCUMENTOS POR PAGAR | C9: 650000
B11: CAPITAL | C11: $ ¿
B13: Las operaciones del mes fueron las siguientes:
B15: 02.02 | C15: Se abre cuenta corriente con el 90% del efectivo.
B16: 03.02 | C16: Se venden materiales por $ 6.500.000 valor total, según factura N° 7. Condiciones 30% contado y resto a crédito simple. Costo de la mercadería vendida se determina considerando que se vendió un 40% de los materiales iniciales.
B17: 04.02 | C17: Se deposita en la cuenta corriente el efectivo de la venta del día 03 de febrero.
B18: 10.02 | C18: Se paga cuentas de luz con cheque N° 1 y agua con cheque N° 2, según boletas N° 234 y 908, por $ 27.000 y $ 15.500, respectivamente.
B19: 16.02 | C19: Se paga en efectivo $ 90.000 correspondiente a arriendo del mes. Además, se pagan 2 meses adelantados con cheque.
B20: 28.02 | C20: Se paga remuneraciones del mes por $1.000.000, con cheque.
B21: 30.04 | C21: Se compra un repuesto para el vehículo con factura N° 3047, valor total $160.000, además se le efectúa una mantención por $120.000 neto.
B22: 30.06 | C22: Se refleja en la cuenta bancaria $ 32.000, correspondiente a intereses cobrados por cuenta corriente.
B23: 28.07 | C23: Se adquieren herramientas para ser utilizadas en la empresa $2.500.000 valor total, se paga el 50% con cheque y el resto al crédito simple.
B24: 31.12 | C24: El cliente de la venta del día 03.02 cancela su deuda con un cheque al día.

Sheet Libro Diario y Mayor
B1: DESARROLLO CERTAMEN DE CONTABILIDAD
B4: Libro Diario | G4: Puntos
B5: 40940 | C5: 1 | I5: Caja | L5: Letras por Pagar
B6: Caja | E6: 5000000 | I6: =+E6 -> 5000000 | J6: =+F14 -> 4500000 | L6: 0 | M6: =+F9 -> 650000
B7: Mercaderias | E7: 10000000 | I7: =+E17 -> 1950000 | J7: =+F29 -> 1950000 | L7: 0 | M7: 0
B8: Depósito a Plazo | E8: 6500000 | I8: 0 | J8: =+F42 -> 90000 | L8: =SUM(L6:L7) -> 0 | M8: =SUM(M6:M7) -> 650000 | N8: SA
C9: Letras Por pagar | F9: 650000 | I9: 0 | J9: 0
C10: Capital | F10: =+E6+E7+E8-F9 -> 20850000 | I10: =SUM(I6:I9) -> 6950000 | J10: =SUM(J6:J9) -> 6540000
B11: Glosa: Asiento de apertura | I11: =+I10-J10 -> 410000 | J11: SD
B12: 40941 | C12: 2
B13: Banco | E13: =+E6*90% -> 4500000
C14: Caja | F14: =+E13 -> 4500000 | I14: Mercadería | L14: Capital
B15: Glosa: Apertura de cuenta corriente | I15: =+E7 -> 10000000 | J15: =+F24 -> 4000000 | L15: 0 | M15: =+F10 -> 20850000
B16: 40942 | C16: 3 | I16: 0 | J16: 0 | L16: 0 | M16: 0
B17: Caja | E17: 1950000 | I17: =SUM(I15:I16) -> 10000000 | J17: =SUM(J15:J16) -> 4000000 | L17: =SUM(L15:L16) -> 0 | M17: =SUM(M15:M16) -> 20850000 | N17: SA
B18: Clientes | E18: 4550000 | I18: =+I17-J17 -> 6000000 | J18: SD
C19: Ingresos por Ventas | F19: 5462185
C20: Iva Débito Fiscal | F20: 1037815
B21: Glosa: Contabiliza venta de mercaderias | I21: Vehiculo | L21: Ingresos por Ventas
B22: 40942 | C22: 4 | I22: =+E8 -> 6500000 | J22: 0 | L22: 0 | M22: =+F19 -> 5462185
B23: Costo de Ventas | E23: 4000000 | I23: =+E36 -> 0 | J23: 0 | L23: 0 | M23: 0
C24: Mercaderias | F24: =+E23 -> 4000000 | I24: =SUM(I22:I23) -> 6500000 | J24: =SUM(J22:J23) -> 0 | L24: =SUM(L22:L23) -> 0 | M24: =SUM(M22:M23) -> 5462185 | N24: SA
B25: Glosa: Contabiliza el costo de la mercadería | I25: =+I24-J24 -> 6500000 | J25: SD
B26: 40943 | C26: 5
B27: Banco | E27: 1950000
C29: Caja | F29: =+E27 -> 1950000 | I29: Banco | L29: Iva Débito Fiscal
B30: Glosa: Depósito venta día 3.02.2012 | I30: =+E13 -> 4500000 | J30: =+F33 -> 42500 | L30: =+E70 -> 1037815 | M30: =+F20 -> 1037815
B31: 40949 | C31: 6 | I31: =+E27 -> 1950000 | J31: =+F43 -> 180000 | L31: 0 | M31: 0
B32: Gastos Generales | E32: =27000+15500 -> 42500 | I32: =+E66 -> 4550000 | J32: =+F47 -> 1000000 | L32: =SUM(L30:L31) -> 1037815 | M32: =SUM(M30:M31) -> 1037815
C33: Banco | F33: =+E32 -> 42500 | I33: 0 | J33: =+F56 -> 32000
B34: Glosa: Se cancela luz y agua con cheques | I34: 0 | J34: =+F62 -> 1250000
I35: 0 | J35: =+F52 -> 302800
I36: =SUM(I30:I35) -> 11000000 | J36: =SUM(J30:J35) -> 2807300
I37: =+I36-J36 -> 8192700 | J37: SD
B39: 40955 | C39: 7
B40: Arriendo | E40: 90000 | I40: Clientes
B41: Arriendo Anticipado | E41: 180000 | I41: =+E18 -> 4550000 | J41: =+F67 -> 4550000 | L41: Acreedores
C42: Caja | F42: =+E40 -> 90000 | I42: 0 | J42: 0 | L42: 0 | M42: 0
C43: Banco | F43: =+E41 -> 180000 | I43: =SUM(I41:I42) -> 4550000 | J43: =SUM(J41:J42) -> 4550000 | L43: 0 | M43: =+F63 -> 1250000
B44: Glosa: Cancela arriendo y anticipo de arriendo | L44: =SUM(L42:L43) -> 0 | M44: =SUM(M42:M43) -> 1250000
...

Sheet Balance 8 columnas
A1: BALANCE 8 COLUMNAS
A3: CUENTAS | B3: DEBITOS | C3: CREDITOS | D3: SALDO DEUDOR | E3: SALDO ACREEDOR | F3: ACTIVOS | G3: PASIVOS | H3: PERDIDAS | I3: GANANCIAS
A4: =+'Libro Diario y Mayor'!I5 -> Caja | B4: =+'Libro Diario y Mayor'!I10 -> 6950000 | C4: =+'Libro Diario y Mayor'!J10 -> 6540000 | D4: =+'Libro Diario y Mayor'!I11 -> 410000 | E4: - | F4: =+D4 -> 410000 | G4: - | H4: - | I4: -
A5: =+'Libro Diario y Mayor'!I29 -> Banco | B5: =+'Libro Diario y Mayor'!I36 -> 11000000 | C5: =+'Libro Diario y Mayor'!J36 -> 2807300 | D5: =+'Libro Diario y Mayor'!I37 -> 8192700 | E5: - | F5: =+D5 -> 8192700 | G5: - | H5: - | I5: -
A6: =+'Libro Diario y Mayor'!I21 -> Vehiculo | B6: =+'Libro Diario y Mayor'!I24 -> 6500000 | C6: =+'Libro Diario y Mayor'!J24 -> 0 | D6: =+'Libro Diario y Mayor'!I25 -> 6500000 | E6: - | F6: =+D6 -> 6500000 | G6: - | H6: - | I6: -
A7: =+'Libro Diario y Mayor'!I14 -> Mercadería | B7: =+'Libro Diario y Mayor'!I17 -> 10000000 | C7: =+'Libro Diario y Mayor'!J17 -> 4000000 | D7: =+'Libro Diario y Mayor'!I18 -> 6000000 | E7: - | F7: =+D7 -> 6000000 | G7: - | H7: - | I7: -
A8: =+'Libro Diario y Mayor'!I40 -> Clientes | B8: =+'Libro Diario y Mayor'!I43 -> 4550000 | C8: =+'Libro Diario y Mayor'!J43 -> 4550000 | D8: 0 | E8: - | F8: =+D8 -> 0 | G8: - | H8: - | I8: -
A9: =+'Libro Diario y Mayor'!P12 -> 0 | B9: =+'Libro Diario y Mayor'!I69 -> 180000 | C9: =+'Libro Diario y Mayor'!J69 -> 0 | D9: =+'Libro Diario y Mayor'!I69 -> 180000 | E9: - | F9: =+D9 -> 180000 | G9: - | H9: - | I9: -
A10: =+'Libro Diario y Mayor'!L66 -> IVA Crédito Fiscal | B10: =+'Libro Diario y Mayor'!L69 -> 447505.6 | C10: =+'Libro Diario y Mayor'!M69 -> 447506 | D10: 0 | E10: - | F10: =+D10 -> 0 | G10: - | H10: - | I10: -
A11: =+'Libro Diario y Mayor'!L60 -> Maquinas y herramientas | B11: =+'Libro Diario y Mayor'!L63 -> 2100840 | C11: =+'Libro Diario y Mayor'!M63 -> 0 | D11: =+B11 -> 2100840 | E11: - | F11: =+D11 -> 2100840 | G11: - | H11: - | I11: -
A12: =+'Libro Diario y Mayor'!S7 -> 0 | B12: =+'Libro Diario y Mayor'!L8 -> 0 | C12: =+'Libro Diario y Mayor'!M8 -> 650000 | D12: - | E12: =+C12 -> 650000 | F12: - | G12: =+E12 -> 650000 | H12: - | I12: -
A13: =+'Libro Diario y Mayor'!L41 -> Acreedores | B13: =+'Libro Diario y Mayor'!L44 -> 0 | C13: =+'Libro Diario y Mayor'!M44 -> 1250000 | D13: - | E13: =+C13 -> 1250000 | F13: - | G13: =+E13 -> 1250000 | H13: - | I13: -
A14: =+'Libro Diario y Mayor'!L48 -> Impuesto a Pagar | B14: =+'Libro Diario y Mayor'!L51 -> 0 | C14: =+'Libro Diario y Mayor'!M51 -> 590309 | D14: - | E14: =+C14 -> 590309 | F14: - | G14: =+E14 -> 590309 | H14: - | I14: -
A15: =+'Libro Diario y Mayor'!L29 -> Iva Débito Fiscal | B15: =+'Libro Diario y Mayor'!L32 -> 1037815 | C15: =+'Libro Diario y Mayor'!M32 -> 1037815 | D15: - | E15: 0 | F15: - | G15: =+E15 -> 0 | H15: - | I15: -
A16: =+'Libro Diario y Mayor'!L14 -> Capital | B16: =+'Libro Diario y Mayor'!L17 -> 0 | C16: =+'Libro Diario y Mayor'!M17 -> 20850000 | D16: - | E16: =+C16 -> 20850000 | F16: - | G16: =+E16 -> 20850000 | H16: - | I16: -
A17: =+'Libro Diario y Mayor'!I46 -> Costo de Venta | B17: =+'Libro Diario y Mayor'!I49 -> 4000000 | C17: 0 | D17: =+B17 -> 4000000 | E17: - | F17: - | G17: - | H17: =+D17 -> 4000000 | I17: -
A18: =+'Libro Diario y Mayor'!I53 -> Gastos Generales | B18: =+'Libro Diario y Mayor'!I56 -> 296954 | C18: =+'Libro Diario y Mayor'!J56 -> 0 | D18: =+B18 -> 296954 | E18: - | F18: - | G18: - | H18: =+D18 -> 296954 | I18: -
A19: =+'Libro Diario y Mayor'!I60 -> Arriendo | B19: =+'Libro Diario y Mayor'!I63 -> 90000 | C19: =+'Libro Diario y Mayor'!J57 -> 0 | D19: =+B19 -> 90000 | E19: - | F19: - | G19: - | H19: =+D19 -> 90000 | I19: -
A20: =+'Libro Diario y Mayor'!I72 -> Remuneraciones | B20: =+'Libro Diario y Mayor'!I75 -> 1000000 | C20: =+'Libro Diario y Mayor'!J58 -> 0 | D20: =+B20 -> 1000000 | E20: - | F20: - | G20: - | H20: =+D20 -> 1000000 | I20: -
A21: =+'Libro Diario y Mayor'!I78 -> Gastos Financieros | B21: =+'Libro Diario y Mayor'!I81 -> 32000 | C21: =+'Libro Diario y Mayor'!J59 -> 0 | D21: =+B21 -> 32000 | E21: - | F21: - | G21: - | H21: =+D21 -> 32000 | I21: -
A22: =+'Libro Diario y Mayor'!L21 -> Ingresos por Ventas | B22: =+'Libro Diario y Mayor'!L24 -> 0 | C22: =+'Libro Diario y Mayor'!M24 -> 5462185 | D22: - | E22: =+C22 -> 5462185 | F22: - | G22: - | H22: - | I22: =+E22 -> 5462185
A23: Subtotal | B23: =SUM(B4:B22) -> 48185115 | C23: =SUM(C4:C22) -> 48185115 | D23: =SUM(D4:D22) -> 28802494 | E23: =SUM(E4:E22) -> 28802494 | F23: =SUM(F4:F22) -> 23383540 | G23: =SUM(G4:G22) -> 23340309 | H23: =SUM(H4:H22) -> 5418954 | I23: =SUM(I4:I22) -> 5462185
A24: Utilidad del Ejercicio | G24: =+F23-G23 -> 43231 | H24: =+I23-H23 -> 43231
A25: Totales Iguales | B25: =SUM(B23) -> 48185115 | C25: =SUM(C23) -> 48185115 | D25: =SUM(D23) -> 28802494 | E25: =SUM(E23) -> 28802494 | F25: =SUM(F23) -> 23383540 | G25: =SUM(G23:G24) -> 23383540 | H25: =SUM(H23:H24) -> 5462185 | I25: =SUM(I23) -> 5462185

Sheet Rúbrica
B2: Rúbrica de Evaluación: Automatización de Ciclo Contable (Datos Provistos)
B4: Puntaje Total: 100 puntos
B6: 1. Matriz de Evaluación
B8: Criterio | C8: Excelente (Logrado) | D8: Regular (En Proceso) | E8: Insuficiente (No Logrado) | F8: Puntaje
B9: Automatización del Traspaso (Diario a Mayor) | C9: (30 pts) El paso de los datos del Libro Diario al Libro Mayor es 100% automático. El sistema centraliza, agrupa por cuenta y calcula los saldos deudores/acreedores sin intervención manual. | D9: (15 pts) El traspaso es semiautomático (ej. requiere ejecutar procesos manuales por cada cuenta) o presenta errores intermitentes en la clasificación de saldos. | E9: (0 pts) El traspaso requiere digitación manual, o el código/fórmula copia los datos en posiciones fijas sin lógica de agrupación. | F9: 30
B10: Automatización del Balance de Comprobación | C10: (30 pts) El Balance se genera automáticamente a partir de los saldos del Mayor. Cuadra perfectamente en sus columnas (Sumas y Saldos) respetando la partida doble de forma dinámica. | D10: (15 pts) El balance se genera automáticamente pero arrastra errores de lógica, o requiere que el usuario mueva datos manualmente para que cuadre. | E10: (0 pts) El balance no está automatizado, está copiado como texto estático o no se presenta. | F10: 30
B11: Dinamicidad y Escalabilidad (Prueba de Estrés) | C11: (25 pts) Cero "Hardcoding". Si el docente cambia, agrega o elimina un asiento en el Libro Diario, el Mayor y el Balance se recalculan y actualizan instantáneamente de forma correcta. | D11: (12 pts) El sistema funciona con el ejercicio entregado, pero si se cambia un valor o se agrega una fila, la automatización se "rompe" o no detecta los nuevos datos. | E11: (0 pts) Los datos están estáticos (pegados como valores). No hay un motor de automatización real. | F11: 25
B12: Validación de Datos y Alertas | C12: (15 pts) El sistema incluye controles de error visuales o lógicos (ej: alertas si el Diario no cuadra antes de pasar al Mayor, o mensajes de "Balance Cuadrado / Error"). | D12: (7 pts) Incluye validaciones muy básicas que no previenen errores críticos en el flujo de los datos. | E12: (0 pts) No existe ningún control de errores; el sistema permite procesar datos inconsistentes sin advertir al usuario. | F12: 15
